File: Carbopol_Malvern.csv
Action Name;Time (sequence)(s);Time (action)(s);Shear stress(Pa);Shear rate(s-¹);Shear strain(%);Normal force(N);Complex shear strain(%);Frequency(Hz);Complex shear stress(Pa);Shear modulus (elastic component)(Pa);Shear modulus (viscous component)(Pa);Shear modulus (complex component)(Pa);Torque(N m);Angular displacement(rad);Temperature(°C);Gap(mm)
Pre Shear Initial;112,3;1,000;30,54;47,57;4,75275E+003;0,2044;;;;;;;1,284E-003;4,516;20,93;9,1500
Pre Shear Initial;114,3;3,000;53,41;50,00;1,47532E+004;0,1983;;;;;;;2,246E-003;14,02;20,93;9,1500
Pre Shear Initial;116,3;5,000;53,12;50,00;2,47538E+004;0,2052;;;;;;;2,233E-003;23,52;20,93;9,1500
Pre Shear Initial;118,3;7,000;53,19;50,00;3,47551E+004;0,1977;;;;;;;2,236E-003;33,03;20,94;9,1500
Pre Shear Initial;120,3;9,000;53,32;50,00;4,47557E+004;0,2043;;;;;;;2,242E-003;42,53;20,94;9,1500
Pre Shear Initial;122,3;11,00;53,30;50,00;5,47562E+004;0,1982;;;;;;;2,241E-003;52,03;20,94;9,1500
Pre Shear Initial;124,3;13,00;53,26;50,00;6,47567E+004;0,2039;;;;;;;2,240E-003;61,53;20,94;9,1500
Pre Shear Initial;126,3;15,00;53,36;50,00;7,47572E+004;0,1980;;;;;;;2,244E-003;71,04;20,95;9,1500
Pre Shear Initial;128,3;17,00;53,35;50,00;8,47573E+004;0,2032;;;;;;;2,243E-003;80,54;20,95;9,1500
Pre Shear Initial;130,3;19,00;53,29;50,00;9,47579E+004;0,1972;;;;;;;2,241E-003;90,04;20,95;9,1500
Pre Shear Initial;132,3;21,00;53,41;50,00;1,04758E+005;0,2028;;;;;;;2,246E-003;99,54;20,95;9,1500
Pre Shear Initial;134,3;23,00;53,37;50,00;1,14759E+005;0,1971;;;;;;;2,244E-003;109,0;20,95;9,1500
Pre Shear Initial;136,3;25,00;53,27;50,00;1,24759E+005;0,2019;;;;;;;2,240E-003;118,5;20,95;9,1500
Pre Shear Initial;138,3;27,00;53,56;50,00;1,34761E+005;0,1980;;;;;;;2,252E-003;128,1;20,95;9,1500
Pre Shear Initial;140,3;29,00;53,42;50,00;1,44761E+005;0,2016;;;;;;;2,246E-003;137,6;20,95;9,1500
Pre Shear Initial;142,3;31,00;53,48;50,00;1,54762E+005;0,1985;;;;;;;2,249E-003;147,1;20,95;9,1500
Pre Shear Initial;144,3;33,00;53,52;50,00;1,64762E+005;0,2009;;;;;;;2,250E-003;156,6;20,96;9,1500
Pre Shear Initial;146,3;35,00;53,60;50,00;1,74763E+005;0,1986;;;;;;;2,254E-003;166,1;20,96;9,1500
Pre Shear Initial;148,3;37,00;53,55;50,00;1,84763E+005;0,2001;;;;;;;2,251E-003;175,6;20,96;9,1500
Pre Shear Initial;150,3;39,00;53,58;50,00;1,94764E+005;0,1987;;;;;;;2,253E-003;185,1;20,96;9,1500
Pre Shear Initial;152,3;41,00;53,54;50,00;2,04764E+005;0,1998;;;;;;;2,251E-003;194,6;20,96;9,1500
Pre Shear Initial;154,3;43,00;53,52;50,00;2,14765E+005;0,1991;;;;;;;2,251E-003;204,1;20,96;9,1500
Pre Shear Initial;156,3;45,00;53,40;50,00;2,24765E+005;0,1991;;;;;;;2,246E-003;213,6;20,96;9,1500
Pre Shear Initial;158,3;47,00;53,65;50,00;2,34766E+005;0,1987;;;;;;;2,256E-003;223,1;20,96;9,1500
Pre Shear Initial;160,3;49,00;53,54;50,00;2,44767E+005;0,1978;;;;;;;2,251E-003;232,6;20,97;9,1500
Pre Shear Initial;162,3;51,00;53,40;50,00;2,54766E+005;0,1989;;;;;;;2,245E-003;242,1;20,97;9,1500
Pre Shear Initial;164,3;53,00;53,62;50,00;2,64768E+005;0,1969;;;;;;;2,254E-003;251,6;20,97;9,1500
Pre Shear Initial;166,3;55,00;53,46;50,00;2,74768E+005;0,1994;;;;;;;2,248E-003;261,1;20,97;9,1500
Pre Shear Initial;168,3;57,00;53,60;50,00;2,84769E+005;0,1961;;;;;;;2,254E-003;270,6;20,97;9,1500
Pre Shear Initial;170,3;59,00;53,63;50,00;2,94769E+005;0,1994;;;;;;;2,255E-003;280,1;20,97;9,1500
Pre Shear Initial;172,3;61,00;53,66;50,00;3,04770E+005;0,1958;;;;;;;2,256E-003;289,6;20,97;9,1500
Pre Shear Initial;174,3;63,00;53,55;50,00;3,14770E+005;0,2004;;;;;;;2,252E-003;299,1;20,97;9,1500
Pre Shear Initial;176,3;65,00;53,64;50,00;3,24771E+005;0,1954;;;;;;;2,255E-003;308,6;20,97;9,1500
Pre Shear Initial;178,3;67,00;53,51;50,00;3,34771E+005;0,2004;;;;;;;2,250E-003;318,1;20,97;9,1500
Pre Shear Initial;180,3;69,00;53,44;50,00;3,44771E+005;0,1951;;;;;;;2,247E-003;327,6;20,98;9,1500
Pre Shear Initial;182,3;71,00;53,53;50,00;3,54772E+005;0,2008;;;;;;;2,251E-003;337,1;20,98;9,1500
Pre Shear Initial;184,3;73,00;53,61;50,00;3,64773E+005;0,1943;;;;;;;2,254E-003;346,6;20,98;9,1500
Pre Shear Initial;186,3;75,00;53,41;50,00;3,74774E+005;0,1999;;;;;;;2,246E-003;356,1;20,98;9,1500
Pre Shear Initial;188,3;77,00;53,58;50,00;3,84774E+005;0,1943;;;;;;;2,253E-003;365,6;20,98;9,1500
Pre Shear Initial;190,3;79,00;53,55;50,00;3,94775E+005;0,2012;;;;;;;2,252E-003;375,1;20,98;9,1500
Pre Shear Initial;192,3;81,00;53,50;50,00;4,04775E+005;0,1939;;;;;;;2,250E-003;384,6;20,98;9,1500
Pre Shear Initial;194,3;83,00;53,45;50,00;4,14776E+005;0,2004;;;;;;;2,248E-003;394,1;20,98;9,1500
Pre Shear Initial;196,3;85,00;53,48;50,00;4,24776E+005;0,1941;;;;;;;2,249E-003;403,6;20,98;9,1500
Pre Shear Initial;198,3;87,00;53,43;50,00;4,34776E+005;0,2010;;;;;;;2,246E-003;413,1;20,98;9,1500
Pre Shear Initial;200,3;89,00;53,50;50,00;4,44777E+005;0,1941;;;;;;;2,250E-003;422,6;20,98;9,1500
Pre Shear Initial;202,3;91,00;53,55;50,00;4,54778E+005;0,2006;;;;;;;2,252E-003;432,1;20,98;9,1500
Pre Shear Initial;204,3;93,00;53,51;50,00;4,64778E+005;0,1936;;;;;;;2,250E-003;441,6;20,98;9,1500
Pre Shear Initial;206,3;95,00;53,40;50,00;4,74779E+005;0,2000;;;;;;;2,245E-003;451,1;20,98;9,1500
Pre Shear Initial;208,3;97,00;53,52;50,00;4,84780E+005;0,1933;;;;;;;2,250E-003;460,7;20,98;9,1500
Pre Shear Initial;210,3;99,00;53,49;50,00;4,94780E+005;0,1994;;;;;;;2,249E-003;470,2;20,99;9,1500
Pre Shear Initial;212,3;101,0;53,24;50,00;5,04781E+005;0,1940;;;;;;;2,239E-003;479,7;20,99;9,1500
Pre Shear Initial;214,3;103,0;53,51;50,00;5,14781E+005;0,1988;;;;;;;2,250E-003;489,2;20,99;9,1500
Pre Shear Initial;216,3;105,0;53,42;50,00;5,24782E+005;0,1948;;;;;;;2,246E-003;498,7;20,99;9,1500
Pre Shear Initial;218,3;107,0;53,24;50,00;5,34782E+005;0,1989;;;;;;;2,238E-003;508,2;20,99;9,1500
Pre Shear Initial;220,3;109,0;53,61;50,00;5,44783E+005;0,1953;;;;;;;2,254E-003;517,7;20,99;9,1500
Pre Shear Initial;222,3;111,0;53,52;50,00;5,54783E+005;0,1985;;;;;;;2,251E-003;527,2;20,99;9,1500
Pre Shear Initial;224,3;113,0;53,41;50,00;5,64786E+005;0,1954;;;;;;;2,246E-003;536,7;20,99;9,1500
Pre Shear Initial;226,3;115,0;53,43;50,00;5,74785E+005;0,1982;;;;;;;2,247E-003;546,2;20,99;9,1500
Pre Shear Initial;228,3;117,0;53,58;50,00;5,84786E+005;0,1963;;;;;;;2,253E-003;555,7;20,99;9,1500
Pre Shear Initial;230,3;119,0;53,36;50,00;5,94786E+005;0,1973;;;;;;;2,244E-003;565,2;20,99;9,1500
Pre Shear Initial;232,3;121,0;53,33;50,00;6,04786E+005;0,1965;;;;;;;2,242E-003;574,7;20,99;9,1500
Pre Shear Initial;234,3;123,0;53,49;50,00;6,14787E+005;0,1973;;;;;;;2,249E-003;584,2;20,99;9,1500
Pre Shear Initial;236,3;125,0;53,29;50,00;6,24787E+005;0,1972;;;;;;;2,241E-003;593,7;20,99;9,1500
Pre Shear Initial;238,3;127,0;53,36;50,00;6,34788E+005;0,1971;;;;;;;2,244E-003;603,2;20,99;9,1500
Pre Shear Initial;240,3;129,0;53,48;50,00;6,44788E+005;0,1977;;;;;;;2,249E-003;612,7;20,99;9,1500
Pre Shear Initial;242,3;131,0;53,38;50,00;6,54789E+005;0,1959;;;;;;;2,244E-003;622,2;20,99;9,1500
Pre Shear Initial;244,3;133,0;53,36;50,00;6,64791E+005;0,1983;;;;;;;2,244E-003;631,7;20,99;9,1500
Pre Shear Initial;246,3;135,0;53,42;50,00;6,74791E+005;0,1955;;;;;;;2,246E-003;641,2;20,99;9,1500
Pre Shear Initial;248,3;137,0;53,27;50,00;6,84791E+005;0,1991;;;;;;;2,240E-003;650,7;20,99;9,1500
Pre Shear Initial;250,3;139,0;53,31;50,00;6,94791E+005;0,1956;;;;;;;2,242E-003;660,2;20,99;9,1500
Pre Shear Initial;252,3;141,0;53,51;50,00;7,04792E+005;0,2001;;;;;;;2,250E-003;669,7;20,99;9,1500
Pre Shear Initial;254,3;143,0;53,42;50,00;7,14792E+005;0,1951;;;;;;;2,246E-003;679,2;20,99;9,1500
Pre Shear Initial;256,3;145,0;53,31;50,00;7,24793E+005;0,1997;;;;;;;2,242E-003;688,7;20,99;9,1500
Pre Shear Initial;258,3;147,0;53,32;50,00;7,34794E+005;0,1946;;;;;;;2,242E-003;698,2;20,99;9,1500
Pre Shear Initial;260,3;149,0;53,48;50,00;7,44794E+005;0,2003;;;;;;;2,249E-003;707,7;20,99;9,1500
Pre Shear Initial;262,3;151,0;53,31;50,00;7,54795E+005;0,1943;;;;;;;2,241E-003;717,2;20,99;9,1500
Pre Shear Initial;264,3;153,0;53,38;50,00;7,64797E+005;0,2010;;;;;;;2,245E-003;726,7;20,99;9,1500
Pre Shear Initial;266,3;155,0;53,42;50,00;7,74796E+005;0,1945;;;;;;;2,246E-003;736,2;20,99;9,1500
Pre Shear Initial;268,3;157,0;53,41;50,00;7,84796E+005;0,2004;;;;;;;2,246E-003;745,7;20,99;9,1500
Pre Shear Initial;270,3;159,0;53,45;50,00;7,94796E+005;0,1948;;;;;;;2,248E-003;755,2;20,99;9,1500
Pre Shear Initial;272,3;161,0;53,42;50,00;8,04797E+005;0,2018;;;;;;;2,246E-003;764,7;20,99;9,1500
Pre Shear Initial;274,3;163,0;53,21;50,00;8,14798E+005;0,1946;;;;;;;2,237E-003;774,2;20,99;9,1500
Pre Shear Initial;276,3;165,0;53,36;50,00;8,24799E+005;0,2018;;;;;;;2,244E-003;783,7;20,99;9,1500
Pre Shear Initial;278,3;167,0;53,47;50,00;8,34799E+005;0,1943;;;;;;;2,248E-003;793,2;20,99;9,1500
Pre Shear Initial;280,3;169,0;53,42;50,00;8,44800E+005;0,2010;;;;;;;2,246E-003;802,8;20,99;9,1500
Pre Shear Initial;282,3;171,0;53,41;50,00;8,54800E+005;0,1942;;;;;;;2,246E-003;812,3;20,99;9,1500
Pre Shear Initial;284,3;173,0;53,47;50,00;8,64800E+005;0,2009;;;;;;;2,248E-003;821,8;20,99;9,1500
Pre Shear Initial;286,3;175,0;53,32;50,00;8,74801E+005;0,1948;;;;;;;2,242E-003;831,3;20,99;9,1500
Pre Shear Initial;288,3;177,0;53,35;50,00;8,84801E+005;0,2010;;;;;;;2,243E-003;840,8;20,99;9,1500
Pre Shear Initial;290,3;179,0;53,42;50,00;8,94802E+005;0,1954;;;;;;;2,246E-003;850,3;20,99;9,1500
Pre Shear Initial;292,3;181,0;53,37;50,00;9,04803E+005;0,2007;;;;;;;2,244E-003;859,8;20,99;9,1500
Pre Shear Initial;294,3;183,0;53,22;50,00;9,14804E+005;0,1952;;;;;;;2,238E-003;869,3;20,99;9,1500
Pre Shear Initial;296,3;185,0;53,39;50,00;9,24804E+005;0,1999;;;;;;;2,245E-003;878,8;20,99;9,1500
Pre Shear Initial;298,3;187,0;53,39;50,00;9,34805E+005;0,1963;;;;;;;2,245E-003;888,3;21,00;9,1500
Pre Shear Initial;300,3;189,0;53,25;50,00;9,44805E+005;0,2000;;;;;;;2,239E-003;897,8;21,00;9,1500
Pre Shear Initial;302,3;191,0;53,44;50,00;9,54805E+005;0,1961;;;;;;;2,247E-003;907,3;21,00;9,1500
Pre Shear Initial;304,3;193,0;53,34;50,00;9,64806E+005;0,1996;;;;;;;2,243E-003;916,8;21,00;9,1500
Pre Shear Initial;306,3;195,0;53,37;50,00;9,74806E+005;0,1973;;;;;;;2,244E-003;926,3;21,00;9,1500
Pre Shear Initial;308,3;197,0;53,39;50,00;9,84807E+005;0,1993;;;;;;;2,245E-003;935,8;21,00;9,1500
Pre Shear Initial;310,3;199,0;53,41;50,00;9,94807E+005;0,1974;;;;;;;2,246E-003;945,3;21,00;9,1500
Pre Shear Initial;312,3;201,0;53,34;50,00;1,00481E+006;0,1989;;;;;;;2,243E-003;954,8;21,00;9,1500
Pre Shear Initial;314,3;203,0;53,37;50,00;1,01481E+006;0,1978;;;;;;;2,244E-003;964,3;21,00;9,1500
Pre Shear Initial;316,3;205,0;53,48;50,00;1,02481E+006;0,1984;;;;;;;2,249E-003;973,8;21,00;9,1500
Pre Shear Initial;318,3;207,0;53,23;50,00;1,03481E+006;0,1982;;;;;;;2,238E-003;983,3;21,00;9,1500
Pre Shear Initial;320,3;209,0;53,42;50,00;1,04481E+006;0,1976;;;;;;;2,246E-003;992,8;21,00;9,1500
Pre Shear Initial;322,3;211,0;53,48;50,00;1,05481E+006;0,1991;;;;;;;2,249E-003;1,002E+003;21,00;9,1500
Pre Shear Initial;324,3;213,0;53,21;50,00;1,06481E+006;0,1974;;;;;;;2,237E-003;1,012E+003;21,00;9,1500
Pre Shear Initial;326,3;215,0;53,33;50,00;1,07481E+006;0,1995;;;;;;;2,242E-003;1,021E+003;21,00;9,1500
Pre Shear Initial;328,3;217,0;53,52;50,00;1,08481E+006;0,1968;;;;;;;2,250E-003;1,031E+003;21,00;9,1500
Pre Shear Initial;330,3;219,0;53,38;50,00;1,09481E+006;0,2006;;;;;;;2,244E-003;1,040E+003;21,00;9,1500
Pre Shear Initial;332,3;221,0;53,31;50,00;1,10481E+006;0,1967;;;;;;;2,242E-003;1,050E+003;21,00;9,1500
Pre Shear Initial;334,3;223,0;53,40;50,00;1,11482E+006;0,2007;;;;;;;2,245E-003;1,059E+003;21,00;9,1500
Pre Shear Initial;336,3;225,0;53,39;50,00;1,12482E+006;0,1962;;;;;;;2,245E-003;1,069E+003;21,00;9,1500
Pre Shear Initial;338,3;227,0;53,22;50,00;1,13482E+006;0,2016;;;;;;;2,238E-003;1,078E+003;21,00;9,1500
Pre Shear Initial;340,3;229,0;53,31;50,00;1,14482E+006;0,1960;;;;;;;2,241E-003;1,088E+003;21,00;9,1500
Pre Shear Initial;342,3;231,0;53,25;50,00;1,15482E+006;0,2013;;;;;;;2,239E-003;1,097E+003;21,00;9,1500
Pre Shear Initial;344,3;233,0;53,23;50,00;1,16482E+006;0,1954;;;;;;;2,238E-003;1,107E+003;21,00;9,1500
Pre Shear Initial;346,3;235,0;53,40;50,00;1,17482E+006;0,2019;;;;;;;2,245E-003;1,116E+003;20,99;9,1500
Pre Shear Initial;348,3;237,0;53,38;50,00;1,18482E+006;0,1954;;;;;;;2,245E-003;1,126E+003;21,00;9,1500
Pre Shear Initial;350,3;239,0;53,31;50,00;1,19482E+006;0,2022;;;;;;;2,241E-003;1,135E+003;21,00;9,1500
Pre Shear Initial;352,3;241,0;53,34;50,00;1,20482E+006;0,1956;;;;;;;2,243E-003;1,145E+003;21,00;9,1500
Pre Shear Initial;354,3;243,0;53,29;50,00;1,21482E+006;0,2029;;;;;;;2,241E-003;1,154E+003;21,00;9,1500
Pre Shear Initial;356,3;245,0;53,35;50,00;1,22482E+006;0,1959;;;;;;;2,243E-003;1,164E+003;21,00;9,1500
Pre Shear Initial;358,3;247,0;53,32;50,00;1,23482E+006;0,2025;;;;;;;2,242E-003;1,173E+003;21,00;9,1500
Pre Shear Initial;360,3;249,0;53,38;50,00;1,24482E+006;0,1958;;;;;;;2,245E-003;1,183E+003;21,00;9,1500
Pre Shear Initial;362,3;251,0;53,17;50,00;1,25482E+006;0,2033;;;;;;;2,236E-003;1,192E+003;21,00;9,1500
Pre Shear Initial;364,3;253,0;53,25;50,00;1,26482E+006;0,1959;;;;;;;2,239E-003;1,202E+003;21,00;9,1500
Pre Shear Initial;366,3;255,0;53,40;50,00;1,27482E+006;0,2030;;;;;;;2,245E-003;1,211E+003;21,00;9,1500
Pre Shear Initial;368,3;257,0;53,39;50,00;1,28482E+006;0,1967;;;;;;;2,245E-003;1,221E+003;21,00;9,1500
Pre Shear Initial;370,3;259,0;53,17;50,00;1,29482E+006;0,2026;;;;;;;2,236E-003;1,230E+003;21,00;9,1500
Pre Shear Initial;372,3;261,0;53,25;50,00;1,30482E+006;0,1967;;;;;;;2,239E-003;1,240E+003;21,00;9,1500
Pre Shear Initial;374,3;263,0;53,35;50,00;1,31483E+006;0,2027;;;;;;;2,243E-003;1,249E+003;21,00;9,1500
Pre Shear Initial;376,3;265,0;53,28;50,00;1,32483E+006;0,1976;;;;;;;2,240E-003;1,259E+003;21,00;9,1500
Pre Shear Initial;378,3;267,0;53,30;50,00;1,33483E+006;0,2023;;;;;;;2,241E-003;1,268E+003;21,00;9,1500
Pre Shear Initial;380,3;269,0;53,11;50,00;1,34483E+006;0,1972;;;;;;;2,233E-003;1,278E+003;21,00;9,1500
Pre Shear Initial;382,3;271,0;53,28;50,00;1,35483E+006;0,2012;;;;;;;2,240E-003;1,287E+003;21,00;9,1500
Pre Shear Initial;384,3;273,0;53,30;50,00;1,36483E+006;0,1978;;;;;;;2,241E-003;1,297E+003;21,00;9,1500
Pre Shear Initial;386,3;275,0;53,27;50,00;1,37483E+006;0,2011;;;;;;;2,240E-003;1,306E+003;21,00;9,1500
Pre Shear Initial;388,3;277,0;53,27;50,00;1,38483E+006;0,1986;;;;;;;2,240E-003;1,316E+003;21,00;9,1500
Pre Shear Initial;390,3;279,0;53,33;50,00;1,39483E+006;0,2008;;;;;;;2,242E-003;1,325E+003;21,00;9,1500
Pre Shear Initial;392,3;281,0;53,31;50,00;1,40483E+006;0,1990;;;;;;;2,241E-003;1,335E+003;21,00;9,1500
Pre Shear Initial;394,3;283,0;53,13;50,00;1,41483E+006;0,2004;;;;;;;2,234E-003;1,344E+003;21,00;9,1500
Pre Shear Initial;396,3;285,0;53,27;50,00;1,42483E+006;0,1993;;;;;;;2,240E-003;1,354E+003;21,00;9,1500
Pre Shear Initial;398,3;287,0;53,28;50,00;1,43483E+006;0,1994;;;;;;;2,240E-003;1,363E+003;21,00;9,1500
Pre Shear Initial;400,3;289,0;53,18;50,00;1,44483E+006;0,2004;;;;;;;2,236E-003;1,373E+003;21,00;9,1500
Pre Shear Initial;402,3;291,0;53,32;50,00;1,45483E+006;0,1989;;;;;;;2,242E-003;1,382E+003;21,00;9,1500
Pre Shear Initial;404,3;293,0;53,24;50,00;1,46483E+006;0,2007;;;;;;;2,239E-003;1,392E+003;21,00;9,1500
Pre Shear Initial;406,3;295,0;53,22;50,00;1,47483E+006;0,1985;;;;;;;2,238E-003;1,401E+003;21,00;9,1500
Pre Shear Initial;408,3;297,0;53,16;50,00;1,48483E+006;0,2020;;;;;;;2,235E-003;1,411E+003;21,00;9,1500
Pre Shear Initial;410,3;299,0;53,30;50,00;1,49484E+006;0,1988;;;;;;;2,241E-003;1,420E+003;21,00;9,1500
Pre Shear R;413,3;2,000;116,0;497,5;9,61090E+004;0,2194;;;;;;;4,877E-003;91,33;21,00;9,1500
Pre Shear R;417,3;6,000;110,6;500,0;2,96116E+005;0,2219;;;;;;;4,651E-003;281,4;21,00;9,1500
Pre Shear R;421,3;10,00;110,9;500,0;4,96128E+005;0,2229;;;;;;;4,664E-003;471,4;21,00;9,1500
Pre Shear R;425,3;14,00;111,1;500,0;6,96140E+005;0,2214;;;;;;;4,673E-003;661,5;21,00;9,1500
Pre Shear R;429,3;18,00;110,8;500,0;8,96152E+005;0,2198;;;;;;;4,660E-003;851,5;21,00;9,1500
Pre Shear R;433,3;22,00;111,0;500,0;1,09616E+006;0,2211;;;;;;;4,668E-003;1,042E+003;21,00;9,1500
Pre Shear R;437,3;26,00;111,1;500,0;1,29617E+006;0,2234;;;;;;;4,673E-003;1,232E+003;21,00;9,1500
Pre Shear R;441,3;30,00;110,9;500,0;1,49618E+006;0,2221;;;;;;;4,664E-003;1,422E+003;21,00;9,1500
Pre Shear R;445,3;34,00;111,1;500,0;1,69620E+006;0,2205;;;;;;;4,670E-003;1,612E+003;21,00;9,1500
Pre Shear R;449,3;38,00;111,1;500,0;1,89621E+006;0,2216;;;;;;;4,672E-003;1,802E+003;21,00;9,1500
Pre Shear R;453,3;42,00;110,9;500,0;2,09621E+006;0,2233;;;;;;;4,663E-003;1,992E+003;21,00;9,1500
Pre Shear R;457,3;46,00;111,1;500,0;2,29623E+006;0,2215;;;;;;;4,671E-003;2,182E+003;21,00;9,1500
Pre Shear R;461,3;50,00;110,9;500,0;2,49624E+006;0,2202;;;;;;;4,663E-003;2,372E+003;21,00;9,1500
Pre Shear R;465,3;54,00;110,8;500,0;2,69625E+006;0,2213;;;;;;;4,659E-003;2,562E+003;21,00;9,1500
Pre Shear R;469,3;58,00;111,1;500,0;2,89626E+006;0,2230;;;;;;;4,671E-003;2,752E+003;21,00;9,1500
Rest R;472,3;1,000;0,000;66,67;5,20820E+003;0,1975;;;;;;;0,000;4,949;21,00;9,1500
Rest R;474,3;3,000;0,000;9,594E-004;5,20843E+003;0,1973;;;;;;;0,000;4,949;21,00;9,1500
Rest R;476,3;5,000;0,000;5,483E-005;5,20844E+003;0,1970;;;;;;;0,000;4,949;21,00;9,1500
Rest R;478,3;7,000;0,000;6,365E-005;5,20843E+003;0,1974;;;;;;;0,000;4,949;21,00;9,1500
Rest R;480,3;9,000;0,000;8,556E-005;5,20841E+003;0,1976;;;;;;;0,000;4,949;21,00;9,1500
Rest R;482,3;11,00;0,000;8,795E-005;5,20840E+003;0,1972;;;;;;;0,000;4,949;21,00;9,1500
Rest R;484,3;13,00;0,000;8,412E-005;5,20838E+003;0,1977;;;;;;;0,000;4,949;21,00;9,1500
Rest R;486,3;15,00;0,000;7,968E-005;5,20836E+003;0,1977;;;;;;;0,000;4,949;21,00;9,1500
Rest R;488,3;17,00;0,000;7,363E-005;5,20835E+003;0,1977;;;;;;;0,000;4,949;21,00;9,1500
Rest R;490,3;19,00;0,000;6,975E-005;5,20833E+003;0,1980;;;;;;;0,000;4,949;21,00;9,1500
Flow Curve Down;496,3;5,000;110,7;500,0;2,46236E+005;0,2234;;;;;;;4,656E-003;234,0;21,00;9,1500
Flow Curve Down;506,3;15,01;92,69;315,5;6,03972E+005;0,2168;;;;;;;3,898E-003;573,9;21,00;9,1500
Flow Curve Down;516,3;25,02;79,14;199,1;8,29691E+005;0,2109;;;;;;;3,328E-003;788,4;21,00;9,1500
Flow Curve Down;526,3;35,02;68,53;125,6;9,71955E+005;0,2123;;;;;;;2,881E-003;923,6;21,00;9,1500
Flow Curve Down;536,3;45,03;60,26;79,25;1,06183E+006;0,2043;;;;;;;2,534E-003;1,009E+003;21,00;9,1500
Flow Curve Down;546,4;55,05;53,51;50,00;1,11861E+006;0,2032;;;;;;;2,250E-003;1,063E+003;21,00;9,1500
Flow Curve Down;556,4;65,06;48,11;31,55;1,15438E+006;0,2014;;;;;;;2,023E-003;1,097E+003;21,00;9,1500
Flow Curve Down;566,4;75,07;43,71;19,91;1,17695E+006;0,2023;;;;;;;1,838E-003;1,118E+003;21,00;9,1500
Flow Curve Down;576,4;85,07;40,00;12,56;1,19117E+006;0,1977;;;;;;;1,682E-003;1,132E+003;21,00;9,1500
Flow Curve Down;586,4;95,08;36,87;7,925;1,20016E+006;0,1964;;;;;;;1,550E-003;1,140E+003;21,00;9,1500
Flow Curve Down;596,4;105,1;34,13;5,000;1,20584E+006;0,1942;;;;;;;1,435E-003;1,146E+003;21,00;9,1500
Flow Curve Down;606,4;115,1;31,68;3,155;1,20942E+006;0,1976;;;;;;;1,332E-003;1,149E+003;21,00;9,1500
Flow Curve Down;616,4;125,1;29,19;1,991;1,21167E+006;0,1934;;;;;;;1,227E-003;1,151E+003;21,00;9,1500
Flow Curve Down;626,4;135,1;26,74;1,256;1,21310E+006;0,1942;;;;;;;1,124E-003;1,153E+003;21,00;9,1500
Flow Curve Down;636,4;145,1;24,79;0,7925;1,21400E+006;0,1967;;;;;;;1,042E-003;1,154E+003;21,00;9,1500
Flow Curve Down;646,4;155,1;23,23;0,5000;1,21456E+006;0,1986;;;;;;;9,766E-004;1,154E+003;21,00;9,1500
Flow Curve Down;656,5;165,2;21,92;0,3155;1,21492E+006;0,1980;;;;;;;9,215E-004;1,154E+003;21,00;9,1500
Flow Curve Down;666,5;175,2;20,80;0,1991;1,21515E+006;0,1999;;;;;;;8,745E-004;1,155E+003;21,00;9,1500
Flow Curve Down;676,5;185,2;19,81;0,1256;1,21529E+006;0,1998;;;;;;;8,331E-004;1,155E+003;21,00;9,1500
Flow Curve Down;686,5;195,2;18,93;0,07925;1,21538E+006;0,2004;;;;;;;7,960E-004;1,155E+003;21,00;9,1500
Flow Curve Down;696,5;205,2;18,16;0,05001;1,21544E+006;0,2005;;;;;;;7,636E-004;1,155E+003;21,00;9,1500
Flow Curve Down;706,5;215,2;17,47;0,03159;1,21547E+006;0,2013;;;;;;;7,347E-004;1,155E+003;21,00;9,1500
Flow Curve Down;716,5;225,2;16,93;0,01982;1,21549E+006;0,2013;;;;;;;7,119E-004;1,155E+003;21,00;9,1500
Flow Curve Down;726,5;235,2;16,48;0,01249;1,21551E+006;0,2011;;;;;;;6,930E-004;1,155E+003;21,00;9,1500
Flow Curve Down;736,5;245,2;16,12;7,869E-003;1,21552E+006;0,2014;;;;;;;6,777E-004;1,155E+003;21,00;9,1500
Flow Curve Down;746,5;255,2;15,82;4,960E-003;1,21552E+006;0,2011;;;;;;;6,653E-004;1,155E+003;21,00;9,1500
Flow Curve Down;756,6;265,3;15,58;3,121E-003;1,21553E+006;0,2016;;;;;;;6,553E-004;1,155E+003;21,00;9,1500
Flow Curve Down;766,6;275,3;15,39;1,970E-003;1,21553E+006;0,2006;;;;;;;6,469E-004;1,155E+003;21,00;9,1500
Flow Curve Down;776,6;285,3;15,22;1,243E-003;1,21553E+006;0,2007;;;;;;;6,398E-004;1,155E+003;21,00;9,1500
Flow Curve Up;786,6;5,000;10,04;9,303E-004;-5,46169;0,2011;;;;;;;4,223E-004;-5,190E-003;21,00;9,1500
Flow Curve Up;796,6;15,00;11,78;1,530E-003;-4,12980;0,2004;;;;;;;4,952E-004;-3,924E-003;21,00;9,1500
Flow Curve Up;806,6;25,01;13,88;2,448E-003;-1,93577;0,2019;;;;;;;5,838E-004;-1,839E-003;21,00;9,1500
Flow Curve Up;816,6;35,01;15,88;4,043E-003;1,64353;0,2008;;;;;;;6,678E-004;1,562E-003;21,00;9,1500
Flow Curve Up;826,6;45,02;16,14;6,355E-003;7,30741;0,2002;;;;;;;6,788E-004;6,944E-003;21,00;9,1500
Flow Curve Up;836,6;55,04;16,38;0,01007;16,2784;0,2004;;;;;;;6,887E-004;0,01547;21,00;9,1500
Flow Curve Up;846,7;65,06;16,72;0,01594;30,5299;0,2007;;;;;;;7,029E-004;0,02901;21,00;9,1500
Flow Curve Up;856,7;75,08;17,12;0,02519;53,0678;0,2022;;;;;;;7,197E-004;0,05043;21,00;9,1500
Flow Curve Up;866,7;85,09;17,56;0,03977;88,7753;0,2018;;;;;;;7,384E-004;0,08436;21,00;9,1500
Flow Curve Up;876,7;95,10;18,14;0,06309;145,351;0,2024;;;;;;;7,628E-004;0,1381;21,00;9,1500
Flow Curve Up;886,7;105,1;18,90;0,1000;234,979;0,2032;;;;;;;7,947E-004;0,2233;21,00;9,1500
Flow Curve Up;896,7;115,1;19,86;0,1585;377,119;0,2026;;;;;;;8,349E-004;0,3583;21,00;9,1500
Flow Curve Up;906,7;125,1;21,03;0,2512;602,413;0,1987;;;;;;;8,842E-004;0,5724;21,00;9,1500
Flow Curve Up;916,7;135,2;22,28;0,3981;958,776;0,1953;;;;;;;9,367E-004;0,9111;21,00;9,1500
Flow Curve Up;926,8;145,2;23,66;0,6310;1,52456E+003;0,1942;;;;;;;9,949E-004;1,449;21,00;9,1500
Flow Curve Up;936,8;155,2;25,35;1,000;2,42040E+003;0,1914;;;;;;;1,066E-003;2,300;21,00;9,1500
Flow Curve Up;946,8;165,2;27,48;1,585;3,83924E+003;0,1915;;;;;;;1,156E-003;3,648;21,00;9,1500
Flow Curve Up;956,8;175,2;30,11;2,512;6,09179E+003;0,1976;;;;;;;1,266E-003;5,789;21,00;9,1500
Flow Curve Up;966,8;185,2;32,53;3,981;9,65879E+003;0,1936;;;;;;;1,368E-003;9,178;21,00;9,1500
Flow Curve Up;976,8;195,2;35,09;6,310;1,53073E+004;0,1958;;;;;;;1,475E-003;14,55;21,00;9,1500
Flow Curve Up;986,8;205,2;37,96;10,00;2,42594E+004;0,1964;;;;;;;1,596E-003;23,05;21,00;9,1500
Flow Curve Up;996,8;215,2;41,29;15,85;3,84723E+004;0,2012;;;;;;;1,736E-003;36,56;21,00;9,1500
Flow Curve Up;1,007E+003;225,2;45,33;25,12;6,09746E+004;0,2032;;;;;;;1,906E-003;57,94;21,00;9,1500
Flow Curve Up;1,017E+003;235,2;50,24;39,81;9,66368E+004;0,2005;;;;;;;2,112E-003;91,83;21,00;9,1500
Flow Curve Up;1,027E+003;245,3;56,13;63,10;1,53176E+005;0,2090;;;;;;;2,360E-003;145,6;21,00;9,1500
Flow Curve Up;1,037E+003;255,3;63,59;100,0;2,42707E+005;0,2052;;;;;;;2,674E-003;230,6;21,00;9,1500
Flow Curve Up;1,047E+003;265,3;72,95;158,5;3,84678E+005;0,2144;;;;;;;3,067E-003;365,5;21,00;9,1500
Flow Curve Up;1,057E+003;275,3;84,97;251,2;6,09915E+005;0,2182;;;;;;;3,573E-003;579,6;21,00;9,1500
Flow Curve Up;1,067E+003;285,3;100,8;398,1;9,66632E+005;0,2226;;;;;;;4,238E-003;918,5;21,00;9,1500
Oscillation Frequency Table;1,472E+003;400,0;;;;0,1982;0,763941;0,01000;1,000;130,1;14,59;130,9;4,205E-005;7,259E-004;21,00;9,1500
Oscillation Frequency Table;2,042E+003;970,1;;;;0,1970;0,726642;0,01585;1,000;137,2;10,67;137,6;4,205E-005;6,905E-004;21,00;9,1500
Oscillation Frequency Table;2,402E+003;1,330E+003;;;;0,1948;0,712416;0,02512;1,000;140,1;9,396;140,4;4,205E-005;6,770E-004;21,00;9,1500
Oscillation Frequency Table;2,629E+003;1,557E+003;;;;0,1950;0,701122;0,03981;1,000;142,4;8,571;142,6;4,205E-005;6,662E-004;21,00;9,1500
Oscillation Frequency Table;2,772E+003;1,700E+003;;;;0,1948;0,692831;0,06310;1,000;144,1;7,919;144,3;4,205E-005;6,583E-004;21,00;9,1500
Oscillation Frequency Table;2,862E+003;1,790E+003;;;;0,1933;0,684567;0,1000;1,000;145,9;7,494;146,1;4,205E-005;6,505E-004;21,00;9,1500
Oscillation Frequency Table;2,919E+003;1,848E+003;;;;0,1946;0,677202;0,1585;1,000;147,5;7,251;147,7;4,206E-005;6,435E-004;21,00;9,1500
Oscillation Frequency Table;2,959E+003;1,887E+003;;;;0,1945;0,670343;0,2512;1,001;149,1;7,184;149,3;4,207E-005;6,370E-004;21,00;9,1500
Oscillation Frequency Table;2,988E+003;1,916E+003;;;;0,1943;0,663892;0,3981;1,002;150,7;7,357;150,9;4,212E-005;6,308E-004;21,00;9,1500
Oscillation Frequency Table;3,011E+003;1,939E+003;;;;0,1941;0,658136;0,6310;1,004;152,4;7,814;152,6;4,222E-005;6,254E-004;21,00;9,1500
Oscillation Frequency Table;3,029E+003;1,957E+003;;;;0,1946;0,654536;1,000;1,010;154,1;8,509;154,4;4,248E-005;6,220E-004;21,00;9,1500
Oscillation Frequency Table;3,044E+003;1,972E+003;;;;0,1948;0,656508;1,585;1,026;156,0;9,544;156,3;4,314E-005;6,238E-004;21,00;9,1500
Oscillation Frequency Table;3,057E+003;1,985E+003;;;;0,1937;0,673649;2,512;1,067;158,0;11,04;158,4;4,486E-005;6,401E-004;21,00;9,1500
Oscillation Frequency Table;3,068E+003;1,996E+003;;;;0,1934;0,736590;3,981;1,184;160,2;13,23;160,7;4,978E-005;6,999E-004;21,00;9,1500
Oscillation Frequency Table;3,080E+003;2,008E+003;;;;0,1938;0,984872;6,310;1,611;162,7;16,96;163,6;6,775E-005;9,359E-004;21,00;9,1500
Oscillation Frequency Table;3,091E+003;2,019E+003;;;;0,1921;3,28186;10,00;5,003;149,9;27,65;152,5;2,104E-004;3,119E-003;21,00;9,1500
Oscillation Frequency Table;3,101E+003;2,029E+003;;;;0,1925;0,389784;15,85;0,6720;170,4;25,91;172,4;2,826E-005;3,704E-004;21,00;9,1500
Oscillation Frequency Table;3,111E+003;2,040E+003;;;;0,1934;0,218539;20,00;0,3857;175,4;19,57;176,5;1,622E-005;2,077E-004;21,00;9,1500
Pre Shear O Repeat;3,115E+003;4,000;109,3;500,0;1,81343E+005;0,2038;;;;;;;4,594E-003;172,3;21,00;9,1500
Pre Shear O Repeat;3,119E+003;8,000;109,5;500,0;3,81354E+005;0,2022;;;;;;;4,606E-003;362,4;21,00;9,1500
Pre Shear O Repeat;3,123E+003;12,00;109,7;500,0;5,81360E+005;0,2017;;;;;;;4,611E-003;552,4;21,00;9,1500
Pre Shear O Repeat;3,127E+003;16,00;109,7;500,0;7,81373E+005;0,2034;;;;;;;4,613E-003;742,5;21,00;9,1500
Pre Shear O Repeat;3,131E+003;20,00;109,7;500,0;9,81387E+005;0,2044;;;;;;;4,613E-003;932,5;21,00;9,1500
Pre Shear O Repeat;3,135E+003;24,00;109,7;500,0;1,18140E+006;0,2019;;;;;;;4,614E-003;1,123E+003;21,00;9,1500
Pre Shear O Repeat;3,139E+003;28,00;109,7;500,0;1,38140E+006;0,2008;;;;;;;4,614E-003;1,313E+003;21,00;9,1500
Pre Shear O Repeat;3,143E+003;32,00;109,7;500,0;1,58142E+006;0,2031;;;;;;;4,613E-003;1,503E+003;21,00;9,1500
Pre Shear O Repeat;3,147E+003;36,00;109,7;500,0;1,78143E+006;0,2036;;;;;;;4,612E-003;1,693E+003;21,00;9,1500
Pre Shear O Repeat;3,151E+003;40,00;109,7;500,0;1,98144E+006;0,2016;;;;;;;4,611E-003;1,883E+003;21,00;9,1500
Pre Shear O Repeat;3,155E+003;44,00;109,7;500,0;2,18145E+006;0,2005;;;;;;;4,611E-003;2,073E+003;21,00;9,1500
Pre Shear O Repeat;3,159E+003;48,00;109,6;500,0;2,38146E+006;0,2032;;;;;;;4,610E-003;2,263E+003;21,00;9,1500
Pre Shear O Repeat;3,163E+003;52,00;109,6;500,0;2,58147E+006;0,2040;;;;;;;4,609E-003;2,453E+003;21,00;9,1500
Pre Shear O Repeat;3,167E+003;56,00;109,6;500,0;2,78149E+006;0,2017;;;;;;;4,609E-003;2,643E+003;21,00;9,1500
Pre Shear O Repeat;3,171E+003;60,00;109,6;500,0;2,98150E+006;0,2008;;;;;;;4,609E-003;2,833E+003;21,00;9,1500
Rest O Repeat;3,173E+003;2,000;0,000;6,797;5,31773E+003;0,1761;;;;;;;0,000;5,053;21,00;9,1500
Rest O Repeat;3,175E+003;4,000;0,000;3,226E-004;5,31780E+003;0,1769;;;;;;;0,000;5,053;21,00;9,1500
Rest O Repeat;3,177E+003;6,000;0,000;9,458E-007;5,31780E+003;0,1766;;;;;;;0,000;5,053;21,00;9,1500
Rest O Repeat;3,179E+003;8,000;0,000;6,246E-005;5,31779E+003;0,1771;;;;;;;0,000;5,053;21,00;9,1500
Rest O Repeat;3,181E+003;10,00;0,000;7,213E-005;5,31777E+003;0,1777;;;;;;;0,000;5,053;21,00;9,1500
Rest O Repeat;3,183E+003;12,00;0,000;7,457E-005;5,31776E+003;0,1779;;;;;;;0,000;5,053;21,00;9,1500
Rest O Repeat;3,185E+003;14,00;0,000;7,125E-005;5,31774E+003;0,1777;;;;;;;0,000;5,053;21,00;9,1500
Rest O Repeat;3,187E+003;16,00;0,000;6,663E-005;5,31773E+003;0,1779;;;;;;;0,000;5,053;21,00;9,1500
Rest O Repeat;3,189E+003;18,00;0,000;6,383E-005;5,31772E+003;0,1779;;;;;;;0,000;5,053;21,00;9,1500
Rest O Repeat;3,191E+003;20,00;0,000;6,080E-005;5,31770E+003;0,1789;;;;;;;0,000;5,053;21,00;9,1500
Oscillation Amplitude Table;3,211E+003;20,02;;;;0,1792;0,0117140;1,000;0,01751;149,5;0,3395;149,5;7,362E-007;1,113E-005;21,00;9,1500
Oscillation Amplitude Table;3,231E+003;40,05;;;;0,1802;0,0157975;1,000;0,02348;148,6;4,888;148,6;9,873E-007;1,501E-005;21,00;9,1500
Oscillation Amplitude Table;3,252E+003;60,08;;;;0,1798;0,0213299;1,000;0,03189;149,3;7,787;149,5;1,341E-006;2,027E-005;21,00;9,1500
Oscillation Amplitude Table;3,272E+003;80,12;;;;0,1795;0,0292058;1,000;0,04382;149,8;7,802;150,0;1,842E-006;2,775E-005;21,00;9,1500
Oscillation Amplitude Table;3,292E+003;100,1;;;;0,1805;0,0397211;1,000;0,05987;150,5;8,000;150,7;2,517E-006;3,774E-005;21,00;9,1500
Oscillation Amplitude Table;3,312E+003;120,2;;;;0,1811;0,0541372;1,000;0,08181;150,9;8,227;151,1;3,440E-006;5,144E-005;21,00;9,1500
Oscillation Amplitude Table;3,332E+003;140,2;;;;0,1817;0,0737078;1,000;0,1116;151,2;8,270;151,4;4,693E-006;7,004E-005;21,00;9,1500
Oscillation Amplitude Table;3,352E+003;160,3;;;;0,1810;0,100047;1,000;0,1516;151,3;8,283;151,5;6,374E-006;9,507E-005;21,00;9,1500
Oscillation Amplitude Table;3,372E+003;180,3;;;;0,1819;0,135937;1,000;0,2060;151,3;8,260;151,5;8,661E-006;1,292E-004;21,00;9,1500
Oscillation Amplitude Table;3,392E+003;200,3;;;;0,1808;0,185015;1,000;0,2800;151,1;8,277;151,3;1,177E-005;1,758E-004;21,00;9,1500
Oscillation Amplitude Table;3,412E+003;220,3;;;;0,1811;0,251152;1,000;0,3794;150,8;8,400;151,1;1,595E-005;2,387E-004;21,00;9,1500
Oscillation Amplitude Table;3,432E+003;240,4;;;;0,1817;0,341641;1,000;0,5147;150,4;8,530;150,7;2,164E-005;3,246E-004;21,00;9,1500
Oscillation Amplitude Table;3,452E+003;260,4;;;;0,1826;0,463982;1,000;0,6961;149,8;8,813;150,0;2,927E-005;4,409E-004;21,00;9,1500
Oscillation Amplitude Table;3,472E+003;280,4;;;;0,1819;0,631151;1,000;0,9428;149,1;9,213;149,4;3,964E-005;5,997E-004;21,00;9,1500
Oscillation Amplitude Table;3,492E+003;300,4;;;;0,1816;0,857856;1,000;1,275;148,3;9,832;148,7;5,362E-005;8,152E-004;21,00;9,1500
Oscillation Amplitude Table;3,512E+003;320,5;;;;0,1828;1,16580;1,000;1,719;147,0;10,68;147,4;7,226E-005;1,108E-003;21,00;9,1500
Oscillation Amplitude Table;3,532E+003;340,5;;;;0,1820;1,58604;1,000;2,294;144,2;11,68;144,6;9,646E-005;1,507E-003;21,00;9,1500
Oscillation Amplitude Table;3,552E+003;360,5;;;;0,1824;2,15516;1,000;3,029;140,0;12,86;140,6;1,274E-004;2,048E-003;21,00;9,1500
Oscillation Amplitude Table;3,572E+003;380,6;;;;0,1834;2,93024;1,000;3,980;135,1;14,41;135,8;1,674E-004;2,784E-003;21,00;9,1500
Oscillation Amplitude Table;3,592E+003;400,6;;;;0,1831;3,98374;1,000;5,170;128,8;16,24;129,8;2,174E-004;3,785E-003;21,00;9,1500
Oscillation Amplitude Table;3,612E+003;420,6;;;;0,1828;5,41392;1,000;6,626;121,0;18,31;122,4;2,786E-004;5,144E-003;21,00;9,1500
Oscillation Amplitude Table;3,632E+003;440,7;;;;0,1824;7,35998;1,000;8,363;111,8;20,44;113,6;3,516E-004;6,994E-003;21,00;9,1500
Oscillation Amplitude Table;3,652E+003;460,7;;;;0,1827;10,0006;1,000;10,40;101,5;22,40;104,0;4,371E-004;9,503E-003;21,00;9,1500
Oscillation Amplitude Table;3,672E+003;480,7;;;;0,1815;13,6012;1,000;12,76;90,67;24,01;93,79;5,364E-004;0,01292;21,00;9,1500
Oscillation Amplitude Table;3,692E+003;500,7;;;;0,1808;18,4959;1,000;15,43;79,55;25,20;83,44;6,489E-004;0,01758;21,00;9,1500
Oscillation Amplitude Table;3,712E+003;520,8;;;;0,1801;25,1712;1,000;18,38;68,25;25,98;73,02;7,729E-004;0,02392;21,00;9,1500
Oscillation Amplitude Table;3,732E+003;540,8;;;;0,1781;34,3179;1,000;21,48;56,72;26,49;62,60;9,033E-004;0,03261;21,00;9,1500
Oscillation Amplitude Table;3,752E+003;560,8;;;;0,1777;46,8851;1,000;24,58;45,07;26,78;52,43;1,034E-003;0,04455;21,00;9,1500
Oscillation Amplitude Table;3,772E+003;580,9;;;;0,1766;64,9870;1,000;27,69;33,47;26,37;42,61;1,164E-003;0,06175;21,00;9,1500
Oscillation Amplitude Table;3,792E+003;600,9;;;;0,1747;87,0167;1,000;30,42;24,53;24,91;34,96;1,279E-003;0,08269;21,00;9,1500
Oscillation Amplitude Table;3,812E+003;620,9;;;;0,1722;121,820;1,000;33,85;16,70;22,21;27,79;1,423E-003;0,1158;21,00;9,1500
Oscillation Amplitude Table;3,832E+003;641,0;;;;0,1706;160,702;1,000;36,20;11,34;19,47;22,53;1,522E-003;0,1527;21,00;9,1500
Oscillation Amplitude Table;3,852E+003;661,0;;;;0,1692;231,077;1,000;40,01;6,989;15,84;17,31;1,682E-003;0,2196;21,00;9,1500
Oscillation Amplitude Table;3,872E+003;681,0;;;;0,1690;321,087;1,000;44,31;4,436;13,07;13,80;1,863E-003;0,3051;21,00;9,1500
Oscillation Amplitude Table;3,892E+003;701,0;;;;0,1689;423,846;1,000;47,33;2,956;10,77;11,17;1,990E-003;0,4027;21,00;9,1500
Oscillation Amplitude Table;3,912E+003;721,1;;;;0,1684;564,269;1,000;51,77;1,845;8,988;9,175;2,177E-003;0,5362;21,00;9,1500
Oscillation Amplitude Table;3,933E+003;741,1;;;;0,1689;745,695;1,000;56,03;1,192;7,418;7,514;2,356E-003;0,7086;21,00;9,1500
Oscillation Amplitude Table;3,953E+003;761,1;;;;0,1691;1,00631E+003;1,000;61,11;0,7498;6,026;6,073;2,570E-003;0,9562;21,00;9,1500
Pre Shear SR;3,955E+003;2,000;104,8;466,2;8,44976E+004;0,2065;;;;;;;4,408E-003;80,29;21,00;9,1500
Pre Shear SR;3,957E+003;4,000;107,3;500,0;1,84505E+005;0,2049;;;;;;;4,512E-003;175,3;21,00;9,1500
Pre Shear SR;3,959E+003;6,000;107,8;500,0;2,84510E+005;0,2041;;;;;;;4,531E-003;270,3;21,00;9,1500
Pre Shear SR;3,961E+003;8,000;108,1;500,0;3,84516E+005;0,2044;;;;;;;4,544E-003;365,4;21,00;9,1500
Pre Shear SR;3,963E+003;10,00;108,3;500,0;4,84522E+005;0,2056;;;;;;;4,553E-003;460,4;21,00;9,1500
Pre Shear SR;3,965E+003;12,00;108,4;500,0;5,84529E+005;0,2062;;;;;;;4,560E-003;555,4;21,00;9,1500
Pre Shear SR;3,967E+003;14,00;108,6;500,0;6,84530E+005;0,2081;;;;;;;4,565E-003;650,5;21,00;9,1500
Pre Shear SR;3,969E+003;16,00;108,7;500,0;7,84537E+005;0,2081;;;;;;;4,570E-003;745,5;21,00;9,1500
Pre Shear SR;3,971E+003;18,00;108,8;500,0;8,84543E+005;0,2071;;;;;;;4,573E-003;840,5;21,00;9,1500
Pre Shear SR;3,973E+003;20,00;108,8;500,0;9,84549E+005;0,2066;;;;;;;4,576E-003;935,5;21,00;9,1500
Rest SR;3,975E+003;2,000;0,000;7,312;5,60154E+003;0,1793;;;;;;;0,000;5,323;21,00;9,1500
Rest SR;3,977E+003;4,000;0,000;3,527E-004;5,60162E+003;0,1792;;;;;;;0,000;5,323;21,00;9,1500
Rest SR;3,979E+003;6,000;0,000;1,048E-005;5,60162E+003;0,1797;;;;;;;0,000;5,323;21,00;9,1500
Rest SR;3,981E+003;8,000;0,000;5,252E-005;5,60161E+003;0,1800;;;;;;;0,000;5,323;21,00;9,1500
Rest SR;3,983E+003;10,00;0,000;6,849E-005;5,60160E+003;0,1797;;;;;;;0,000;5,323;21,00;9,1500
Rest SR;3,985E+003;12,00;0,000;7,089E-005;5,60158E+003;0,1804;;;;;;;0,000;5,323;21,00;9,1500
Rest SR;3,987E+003;14,00;0,000;7,035E-005;5,60157E+003;0,1803;;;;;;;0,000;5,323;21,00;9,1500
Rest SR;3,989E+003;16,00;0,000;6,476E-005;5,60155E+003;0,1803;;;;;;;0,000;5,323;21,00;9,1500
Rest SR;3,991E+003;18,00;0,000;6,273E-005;5,60154E+003;0,1806;;;;;;;0,000;5,323;21,00;9,1500
Rest SR;3,993E+003;20,00;0,000;5,926E-005;5,60153E+003;0,1809;;;;;;;0,000;5,323;21,00;9,1500
Oscillation Single Frequency;3,993E+003;0,09375;;;;0,1806;;;;;;;2,958E-006;0,000;21,00;9,1500
Oscillation Single Frequency;3,993E+003;0,1875;;;;0,1809;;;;;;;5,980E-006;4,829E-005;21,00;9,1500
Oscillation Single Frequency;3,993E+003;0,2812;;;;0,1806;;;;;;;8,873E-006;9,518E-005;21,00;9,1500
Oscillation Single Frequency;3,993E+003;0,3750;;;;0,1807;;;;;;;1,157E-005;1,418E-004;21,00;9,1500
Oscillation Single Frequency;3,993E+003;0,4687;;;;0,1806;;;;;;;1,402E-005;1,846E-004;21,00;9,1500
Oscillation Single Frequency;3,993E+003;0,5625;;;;0,1808;;;;;;;1,617E-005;2,233E-004;21,00;9,1500
Oscillation Single Frequency;3,993E+003;0,6562;;;;0,1812;;;;;;;1,797E-005;2,565E-004;21,00;9,1500
Oscillation Single Frequency;3,993E+003;0,7500;;;;0,1811;;;;;;;1,937E-005;2,837E-004;21,00;9,1500
Oscillation Single Frequency;3,993E+003;0,8437;;;;0,1811;;;;;;;2,036E-005;3,050E-004;21,00;9,1500
Oscillation Single Frequency;3,994E+003;0,9375;;;;0,1814;;;;;;;2,091E-005;3,184E-004;21,00;9,1500
Oscillation Single Frequency;3,994E+003;1,031;;;;0,1813;;;;;;;2,100E-005;3,243E-004;21,00;9,1500
Oscillation Single Frequency;3,994E+003;1,125;;;;0,1812;;;;;;;2,064E-005;3,238E-004;21,00;9,1500
Oscillation Single Frequency;3,994E+003;1,219;;;;0,1813;;;;;;;1,984E-005;3,152E-004;21,00;9,1500
Oscillation Single Frequency;3,994E+003;1,312;;;;0,1812;;;;;;;1,860E-005;2,990E-004;21,00;9,1500
Oscillation Single Frequency;3,994E+003;1,406;;;;0,1811;;;;;;;1,696E-005;2,763E-004;21,00;9,1500
Oscillation Single Frequency;3,994E+003;1,500;;;;0,1811;;;;;;;1,496E-005;2,460E-004;21,00;9,1500
Oscillation Single Frequency;3,994E+003;1,594;;;;0,1808;;;;;;;1,263E-005;2,099E-004;21,00;9,1500
Oscillation Single Frequency;3,994E+003;1,687;;;;0,1811;;;;;;;1,002E-005;1,691E-004;21,00;9,1500
Oscillation Single Frequency;3,994E+003;1,781;;;;0,1812;;;;;;;7,203E-006;1,221E-004;21,00;9,1500
Oscillation Single Frequency;3,994E+003;1,875;;;;0,1811;;;;;;;4,227E-006;7,280E-005;21,00;9,1500
Oscillation Single Frequency;3,995E+003;1,969;;;;0,1813;;;;;;;1,159E-006;2,096E-005;21,00;9,1500
Oscillation Single Frequency;3,995E+003;2,062;;;;0,1811;;;;;;;-1,933E-006;-3,332E-005;21,00;9,1500
Oscillation Single Frequency;3,995E+003;2,156;;;;0,1811;;;;;;;-4,984E-006;-8,569E-005;21,00;9,1500
Oscillation Single Frequency;3,995E+003;2,250;;;;0,1812;;;;;;;-7,931E-006;-1,370E-004;21,00;9,1500
Oscillation Single Frequency;3,995E+003;2,344;;;;0,1810;;;;;;;-1,070E-005;-1,856E-004;21,00;9,1500
Oscillation Single Frequency;3,995E+003;2,437;;;;0,1810;;;;;;;-1,324E-005;-2,316E-004;21,00;9,1500
Oscillation Single Frequency;3,995E+003;2,531;;;;0,1810;;;;;;;-1,549E-005;-2,737E-004;21,00;9,1500
Oscillation Single Frequency;3,995E+003;2,625;;;;0,1809;;;;;;;-1,741E-005;-3,110E-004;21,00;9,1500
Oscillation Single Frequency;3,995E+003;2,719;;;;0,1810;;;;;;;-1,895E-005;-3,425E-004;21,00;9,1500
Oscillation Single Frequency;3,995E+003;2,812;;;;0,1807;;;;;;;-2,008E-005;-3,686E-004;21,00;9,1500
Oscillation Single Frequency;3,995E+003;2,906;;;;0,1807;;;;;;;-2,078E-005;-3,855E-004;21,00;9,1500
Oscillation Single Frequency;3,996E+003;3,000;;;;0,1809;;;;;;;-2,102E-005;-3,954E-004;21,00;9,1500
Oscillation Single Frequency;3,996E+003;3,094;;;;0,1808;;;;;;;-2,081E-005;-3,982E-004;21,00;9,1500
Oscillation Single Frequency;3,996E+003;3,187;;;;0,1808;;;;;;;-2,015E-005;-3,928E-004;21,00;9,1500
Oscillation Single Frequency;3,996E+003;3,281;;;;0,1807;;;;;;;-1,906E-005;-3,809E-004;21,00;9,1500
Oscillation Single Frequency;3,996E+003;3,375;;;;0,1803;;;;;;;-1,755E-005;-3,612E-004;21,00;9,1500
Oscillation Single Frequency;3,996E+003;3,469;;;;0,1806;;;;;;;-1,566E-005;-3,348E-004;21,00;9,1500
Oscillation Single Frequency;3,996E+003;3,562;;;;0,1807;;;;;;;-1,343E-005;-3,020E-004;21,00;9,1500
Oscillation Single Frequency;3,996E+003;3,656;;;;0,1809;;;;;;;-1,091E-005;-2,643E-004;21,00;9,1500
Oscillation Single Frequency;3,996E+003;3,750;;;;0,1806;;;;;;;-8,160E-006;-2,218E-004;21,00;9,1500
Oscillation Single Frequency;3,996E+003;3,844;;;;0,1804;;;;;;;-5,228E-006;-1,761E-004;21,00;9,1500
Oscillation Single Frequency;3,997E+003;3,937;;;;0,1809;;;;;;;-2,184E-006;-1,277E-004;21,00;9,1500
Oscillation Single Frequency;3,997E+003;4,031;;;;0,1810;;;;;;;9,079E-007;-7,739E-005;21,00;9,1500
Oscillation Single Frequency;3,997E+003;4,125;;;;0,1807;;;;;;;3,980E-006;-2,715E-005;21,00;9,1500
Oscillation Single Frequency;3,997E+003;4,219;;;;0,1809;;;;;;;6,966E-006;2,552E-005;21,00;9,1500
Oscillation Single Frequency;3,997E+003;4,312;;;;0,1811;;;;;;;9,801E-006;7,495E-005;21,00;9,1500
Oscillation Single Frequency;3,997E+003;4,406;;;;0,1811;;;;;;;1,242E-005;1,215E-004;21,00;9,1500
Oscillation Single Frequency;3,997E+003;4,500;;;;0,1812;;;;;;;1,478E-005;1,652E-004;21,00;9,1500
Oscillation Single Frequency;3,997E+003;4,594;;;;0,1811;;;;;;;1,681E-005;2,027E-004;21,00;9,1500
Oscillation Single Frequency;3,997E+003;4,687;;;;0,1814;;;;;;;1,848E-005;2,344E-004;21,00;9,1500
[...]
Oscillation Single Frequency (5);4,422E+003;148,9;;;;0,1857;;;;;;;-9,193E-005;-3,212E-003;21,00;9,1500
Oscillation Single Frequency (5);4,422E+003;149,0;;;;0,1859;;;;;;;-8,981E-005;-3,177E-003;21,00;9,1500
Oscillation Single Frequency (5);4,422E+003;149,1;;;;0,1857;;;;;;;-8,767E-005;-3,139E-003;21,00;9,1500
Oscillation Single Frequency (5);4,422E+003;149,1;;;;0,1855;;;;;;;-8,550E-005;-3,101E-003;21,00;9,1500
Oscillation Single Frequency (5);4,422E+003;149,2;;;;0,1854;;;;;;;-8,331E-005;-3,063E-003;21,00;9,1500
Oscillation Single Frequency (5);4,422E+003;149,3;;;;0,1854;;;;;;;-8,110E-005;-3,027E-003;21,00;9,1500
Oscillation Single Frequency (5);4,422E+003;149,4;;;;0,1854;;;;;;;-7,886E-005;-2,988E-003;21,00;9,1500
Oscillation Single Frequency (5);4,422E+003;149,5;;;;0,1852;;;;;;;-7,661E-005;-2,949E-003;21,00;9,1500
Oscillation Single Frequency (5);4,422E+003;149,5;;;;0,1851;;;;;;;-7,434E-005;-2,911E-003;21,00;9,1500
Oscillation Single Frequency (5);4,422E+003;149,6;;;;0,1854;;;;;;;-7,204E-005;-2,870E-003;21,00;9,1500
Oscillation Single Frequency (5);4,422E+003;149,7;;;;0,1855;;;;;;;-6,973E-005;-2,829E-003;21,00;9,1500
Oscillation Single Frequency (5);4,422E+003;149,8;;;;0,1858;;;;;;;-6,740E-005;-2,787E-003;21,00;9,1500
Oscillation Single Frequency (5);4,423E+003;149,8;;;;0,1858;;;;;;;-6,506E-005;-2,746E-003;21,00;9,1500
Oscillation Single Frequency (5);4,423E+003;149,9;;;;0,1858;;;;;;;-6,269E-005;-2,704E-003;21,00;9,1500
Oscillation Single Frequency (5);4,423E+003;150,0;;;;0,1852;;;;;;;-6,031E-005;-2,662E-003;21,00;9,1500
Oscillation Single Frequency (5);4,423E+003;150,1;;;;0,1854;;;;;;;-5,791E-005;-2,620E-003;21,00;9,1500
Oscillation Single Frequency (5);4,423E+003;150,2;;;;0,1855;;;;;;;-5,550E-005;-2,578E-003;21,00;9,1500
Oscillation Single Frequency (5);4,423E+003;150,2;;;;0,1858;;;;;;;-5,308E-005;-2,535E-003;21,00;9,1500
Oscillation Single Frequency (5);4,423E+003;150,3;;;;0,1858;;;;;;;-5,064E-005;-2,492E-003;21,00;9,1500
Oscillation Single Frequency (5);4,423E+003;150,4;;;;0,1858;;;;;;;-4,818E-005;-2,449E-003;21,00;9,1500
Oscillation Single Frequency (5);4,423E+003;150,5;;;;0,1861;;;;;;;-4,571E-005;-2,403E-003;21,00;9,1500
Oscillation Single Frequency (5);4,423E+003;150,5;;;;0,1863;;;;;;;-4,323E-005;-2,360E-003;21,00;9,1500
Oscillation Single Frequency (5);4,423E+003;150,6;;;;0,1861;;;;;;;-4,075E-005;-2,313E-003;21,00;9,1500
Oscillation Single Frequency (5);4,423E+003;150,7;;;;0,1862;;;;;;;-3,825E-005;-2,269E-003;21,00;9,1500
Oscillation Single Frequency (5);4,423E+003;150,8;;;;0,1858;;;;;;;-3,574E-005;-2,223E-003;21,00;9,1500
Oscillation Single Frequency (5);4,424E+003;150,9;;;;0,1859;;;;;;;-3,322E-005;-2,177E-003;21,00;9,1500
Oscillation Single Frequency (5);4,424E+003;150,9;;;;0,1862;;;;;;;-3,069E-005;-2,131E-003;21,00;9,1500
Oscillation Single Frequency (5);4,424E+003;151,0;;;;0,1863;;;;;;;-2,815E-005;-2,085E-003;21,00;9,1500
Oscillation Single Frequency (5);4,424E+003;151,1;;;;0,1862;;;;;;;-2,561E-005;-2,040E-003;21,00;9,1500
Oscillation Single Frequency (5);4,424E+003;151,2;;;;0,1859;;;;;;;-2,306E-005;-1,995E-003;21,00;9,1500
Oscillation Single Frequency (5);4,424E+003;151,2;;;;0,1860;;;;;;;-2,050E-005;-1,950E-003;21,00;9,1500
Oscillation Single Frequency (5);4,424E+003;151,3;;;;0,1859;;;;;;;-1,794E-005;-1,903E-003;21,00;9,1500
Oscillation Single Frequency (5);4,424E+003;151,4;;;;0,1858;;;;;;;-1,538E-005;-1,857E-003;21,00;9,1500
Oscillation Single Frequency (5);4,424E+003;151,5;;;;0,1857;;;;;;;-1,281E-005;-1,809E-003;21,00;9,1500
Oscillation Single Frequency (5);4,424E+003;151,6;;;;0,1858;;;;;;;-1,023E-005;-1,763E-003;21,00;9,1500
Oscillation Single Frequency (5);4,424E+003;151,6;;;;0,1860;;;;;;;-7,659E-006;-1,716E-003;21,00;9,1500
Oscillation Single Frequency (5);4,424E+003;151,7;;;;0,1859;;;;;;;-5,081E-006;-1,669E-003;21,00;9,1500
Oscillation Single Frequency (5);4,425E+003;151,8;;;;0,1860;;;;;;;-2,502E-006;-1,622E-003;21,00;9,1500
Oscillation Single Frequency (5);4,425E+003;151,9;;;;0,1860;;;;;;;7,828E-008;-1,575E-003;21,00;9,1500
Oscillation Single Frequency (5);4,425E+003;152,0;;;;0,1858;;;;;;;2,658E-006;-1,525E-003;21,00;9,1500
Oscillation Single Frequency (5);4,425E+003;152,0;;;;0,1856;;;;;;;5,237E-006;-1,477E-003;21,00;9,1500
Oscillation Single Frequency (5);4,425E+003;152,1;;;;0,1858;;;;;;;7,815E-006;-1,425E-003;21,00;9,1500
Oscillation Single Frequency (5);4,425E+003;152,2;;;;0,1855;;;;;;;1,039E-005;-1,376E-003;21,00;9,1500
Oscillation Single Frequency (5);4,425E+003;152,3;;;;0,1856;;;;;;;1,296E-005;-1,327E-003;21,00;9,1500
Oscillation Single Frequency (5);4,425E+003;152,3;;;;0,1854;;;;;;;1,553E-005;-1,277E-003;21,00;9,1500
Oscillation Single Frequency (5);4,425E+003;152,4;;;;0,1855;;;;;;;1,810E-005;-1,227E-003;21,00;9,1500
Oscillation Single Frequency (5);4,425E+003;152,5;;;;0,1856;;;;;;;2,066E-005;-1,178E-003;21,00;9,1500
Oscillation Single Frequency (5);4,425E+003;152,6;;;;0,1857;;;;;;;2,322E-005;-1,128E-003;21,00;9,1500
Oscillation Single Frequency (5);4,425E+003;152,7;;;;0,1858;;;;;;;2,577E-005;-1,078E-003;21,00;9,1500
Oscillation Single Frequency (5);4,425E+003;152,7;;;;0,1858;;;;;;;2,831E-005;-1,029E-003;21,00;9,1500
Oscillation Single Frequency (5);4,426E+003;152,8;;;;0,1855;;;;;;;3,084E-005;-9,795E-004;21,00;9,1500
Oscillation Single Frequency (5);4,426E+003;152,9;;;;0,1853;;;;;;;3,337E-005;-9,301E-004;21,00;9,1500
Oscillation Single Frequency (5);4,426E+003;153,0;;;;0,1854;;;;;;;3,589E-005;-8,801E-004;21,00;9,1500
Oscillation Single Frequency (5);4,426E+003;153,0;;;;0,1855;;;;;;;3,840E-005;-8,309E-004;21,00;9,1500
Oscillation Single Frequency (5);4,426E+003;153,1;;;;0,1854;;;;;;;4,090E-005;-7,830E-004;21,00;9,1500
Oscillation Single Frequency (5);4,426E+003;153,2;;;;0,1853;;;;;;;4,339E-005;-7,340E-004;21,00;9,1500
Oscillation Single Frequency (5);4,426E+003;153,3;;;;0,1854;;;;;;;4,586E-005;-6,859E-004;21,00;9,1500
Oscillation Single Frequency (5);4,426E+003;153,4;;;;0,1858;;;;;;;4,833E-005;-6,354E-004;21,00;9,1500
Oscillation Single Frequency (5);4,426E+003;153,4;;;;0,1859;;;;;;;5,078E-005;-5,866E-004;21,00;9,1500
Oscillation Single Frequency (5);4,426E+003;153,5;;;;0,1856;;;;;;;5,322E-005;-5,379E-004;21,00;9,1500
Oscillation Single Frequency (5);4,426E+003;153,6;;;;0,1857;;;;;;;5,565E-005;-4,888E-004;21,00;9,1500
Oscillation Single Frequency (5);4,426E+003;153,7;;;;0,1856;;;;;;;5,806E-005;-4,396E-004;21,00;9,1500
Oscillation Single Frequency (5);4,426E+003;153,7;;;;0,1857;;;;;;;6,046E-005;-3,913E-004;21,00;9,1500
Oscillation Single Frequency (5);4,427E+003;153,8;;;;0,1860;;;;;;;6,284E-005;-3,443E-004;21,00;9,1500
Oscillation Single Frequency (5);4,427E+003;153,9;;;;0,1859;;;;;;;6,520E-005;-2,968E-004;21,00;9,1500
Oscillation Single Frequency (5);4,427E+003;154,0;;;;0,1856;;;;;;;6,755E-005;-2,505E-004;21,00;9,1500
Oscillation Single Frequency (5);4,427E+003;154,1;;;;0,1859;;;;;;;6,987E-005;-2,046E-004;21,00;9,1500
Oscillation Single Frequency (5);4,427E+003;154,1;;;;0,1858;;;;;;;7,218E-005;-1,586E-004;21,00;9,1500
Oscillation Single Frequency (5);4,427E+003;154,2;;;;0,1857;;;;;;;7,448E-005;-1,124E-004;21,00;9,1500
Oscillation Single Frequency (5);4,427E+003;154,3;;;;0,1855;;;;;;;7,675E-005;-6,645E-005;21,00;9,1500
Oscillation Single Frequency (5);4,427E+003;154,4;;;;0,1855;;;;;;;7,900E-005;-2,088E-005;21,00;9,1500
Oscillation Single Frequency (5);4,427E+003;154,5;;;;0,1858;;;;;;;8,123E-005;2,447E-005;21,00;9,1500
Oscillation Single Frequency (5);4,427E+003;154,5;;;;0,1857;;;;;;;8,344E-005;6,787E-005;21,00;9,1500
Oscillation Single Frequency (5);4,427E+003;154,6;;;;0,1859;;;;;;;8,563E-005;1,128E-004;21,00;9,1500
Oscillation Single Frequency (5);4,427E+003;154,7;;;;0,1856;;;;;;;8,780E-005;1,553E-004;21,00;9,1500
Oscillation Single Frequency (5);4,427E+003;154,8;;;;0,1858;;;;;;;8,994E-005;1,987E-004;21,00;9,1500
Oscillation Single Frequency (5);4,428E+003;154,8;;;;0,1856;;;;;;;9,206E-005;2,442E-004;21,00;9,1500
Oscillation Single Frequency (5);4,428E+003;154,9;;;;0,1858;;;;;;;9,416E-005;2,876E-004;21,00;9,1500
Oscillation Single Frequency (5);4,428E+003;155,0;;;;0,1860;;;;;;;9,623E-005;3,316E-004;21,00;9,1500
Oscillation Single Frequency (5);4,428E+003;155,1;;;;0,1861;;;;;;;9,827E-005;3,731E-004;21,00;9,1500
Oscillation Single Frequency (5);4,428E+003;155,2;;;;0,1859;;;;;;;1,003E-004;4,154E-004;21,00;9,1500
Oscillation Single Frequency (5);4,428E+003;155,2;;;;0,1858;;;;;;;1,023E-004;4,592E-004;21,00;9,1500
Oscillation Single Frequency (5);4,428E+003;155,3;;;;0,1859;;;;;;;1,043E-004;5,012E-004;21,00;9,1500
Oscillation Single Frequency (5);4,428E+003;155,4;;;;0,1862;;;;;;;1,062E-004;5,419E-004;21,00;9,1500
Oscillation Single Frequency (5);4,428E+003;155,5;;;;0,1860;;;;;;;1,081E-004;5,823E-004;21,00;9,1500
Oscillation Single Frequency (5);4,428E+003;155,5;;;;0,1858;;;;;;;1,100E-004;6,223E-004;21,00;9,1500
Oscillation Single Frequency (5);4,428E+003;155,6;;;;0,1858;;;;;;;1,118E-004;6,636E-004;21,00;9,1500
Oscillation Single Frequency (5);4,428E+003;155,7;;;;0,1858;;;;;;;1,137E-004;7,019E-004;21,00;9,1500
Oscillation Single Frequency (5);4,428E+003;155,8;;;;0,1856;;;;;;;1,155E-004;7,398E-004;21,00;9,1500
Oscillation Single Frequency (5);4,429E+003;155,9;;;;0,1859;;;;;;;1,172E-004;7,784E-004;21,00;9,1500
Oscillation Single Frequency (5);4,429E+003;155,9;;;;0,1860;;;;;;;1,190E-004;8,173E-004;21,00;9,1500
Oscillation Single Frequency (5);4,429E+003;156,0;;;;0,1864;;;;;;;1,207E-004;8,532E-004;21,00;9,1500
Oscillation Single Frequency (5);4,429E+003;156,1;;;;0,1865;;;;;;;1,224E-004;8,897E-004;21,00;9,1500
Oscillation Single Frequency (5);4,429E+003;156,2;;;;0,1863;;;;;;;1,240E-004;9,258E-004;21,00;9,1500
Oscillation Single Frequency (5);4,429E+003;156,2;;;;0,1859;;;;;;;1,256E-004;9,602E-004;21,00;9,1500
Oscillation Single Frequency (5);4,429E+003;156,3;;;;0,1860;;;;;;;1,272E-004;9,930E-004;21,00;9,1500
Oscillation Single Frequency (5);4,429E+003;156,4;;;;0,1858;;;;;;;1,287E-004;1,027E-003;21,00;9,1500
Oscillation Single Frequency (5);4,429E+003;156,5;;;;0,1861;;;;;;;1,302E-004;1,064E-003;21,00;9,1500
Oscillation Single Frequency (5);4,429E+003;156,6;;;;0,1864;;;;;;;1,317E-004;1,098E-003;21,00;9,1500
Oscillation Single Frequency (5);4,429E+003;156,6;;;;0,1864;;;;;;;1,331E-004;1,129E-003;21,00;9,1500
Oscillation Single Frequency (5);4,429E+003;156,7;;;;0,1863;;;;;;;1,346E-004;1,162E-003;21,00;9,1500
Oscillation Single Frequency (5);4,430E+003;156,8;;;;0,1862;;;;;;;1,359E-004;1,195E-003;21,00;9,1500
Oscillation Single Frequency (5);4,430E+003;156,9;;;;0,1860;;;;;;;1,373E-004;1,224E-003;21,00;9,1500
Oscillation Single Frequency (5);4,430E+003;157,0;;;;0,1863;;;;;;;1,386E-004;1,255E-003;21,00;9,1500
Oscillation Single Frequency (5);4,430E+003;157,0;;;;0,1864;;;;;;;1,398E-004;1,285E-003;21,00;9,1500
Oscillation Single Frequency (5);4,430E+003;157,1;;;;0,1864;;;;;;;1,411E-004;1,316E-003;21,00;9,1500
Oscillation Single Frequency (5);4,430E+003;157,2;;;;0,1863;;;;;;;1,422E-004;1,344E-003;21,00;9,1500
Oscillation Single Frequency (5);4,430E+003;157,3;;;;0,1864;;;;;;;1,434E-004;1,369E-003;21,00;9,1500
Oscillation Single Frequency (5);4,430E+003;157,3;;;;0,1863;;;;;;;1,445E-004;1,394E-003;21,00;9,1500
Oscillation Single Frequency (5);4,430E+003;157,4;;;;0,1862;;;;;;;1,456E-004;1,419E-003;21,00;9,1500
Oscillation Single Frequency (5);4,430E+003;157,5;;;;0,1860;;;;;;;1,466E-004;1,447E-003;21,00;9,1500
Oscillation Single Frequency (5);4,430E+003;157,6;;;;0,1859;;;;;;;1,476E-004;1,471E-003;21,00;9,1500
Oscillation Single Frequency (5);4,430E+003;157,7;;;;0,1859;;;;;;;1,486E-004;1,493E-003;21,00;9,1500
Oscillation Single Frequency (5);4,430E+003;157,7;;;;0,1860;;;;;;;1,495E-004;1,515E-003;21,00;9,1500
Oscillation Single Frequency (5);4,431E+003;157,8;;;;0,1860;;;;;;;1,504E-004;1,537E-003;21,00;9,1500
Oscillation Single Frequency (5);4,431E+003;157,9;;;;0,1859;;;;;;;1,512E-004;1,556E-003;21,00;9,1500
Oscillation Single Frequency (5);4,431E+003;158,0;;;;0,1859;;;;;;;1,521E-004;1,577E-003;21,00;9,1500
Oscillation Single Frequency (5);4,431E+003;158,0;;;;0,1860;;;;;;;1,528E-004;1,597E-003;21,00;9,1500
Oscillation Single Frequency (5);4,431E+003;158,1;;;;0,1861;;;;;;;1,535E-004;1,617E-003;21,00;9,1500
Oscillation Single Frequency (5);4,431E+003;158,2;;;;0,1863;;;;;;;1,542E-004;1,634E-003;21,00;9,1500
Oscillation Single Frequency (5);4,431E+003;158,3;;;;0,1865;;;;;;;1,549E-004;1,648E-003;21,00;9,1500
Oscillation Single Frequency (5);4,431E+003;158,4;;;;0,1863;;;;;;;1,555E-004;1,666E-003;21,00;9,1500
Oscillation Single Frequency (5);4,431E+003;158,4;;;;0,1863;;;;;;;1,560E-004;1,682E-003;21,00;9,1500
Oscillation Single Frequency (5);4,431E+003;158,5;;;;0,1864;;;;;;;1,566E-004;1,697E-003;21,00;9,1500
Oscillation Single Frequency (5);4,431E+003;158,6;;;;0,1865;;;;;;;1,571E-004;1,711E-003;21,00;9,1500
Oscillation Single Frequency (5);4,431E+003;158,7;;;;0,1864;;;;;;;1,575E-004;1,723E-003;21,00;9,1500
Oscillation Single Frequency (5);4,431E+003;158,7;;;;0,1867;;;;;;;1,579E-004;1,735E-003;21,00;9,1500
Oscillation Single Frequency (5);4,432E+003;158,8;;;;0,1866;;;;;;;1,583E-004;1,746E-003;21,00;9,1500
Oscillation Single Frequency (5);4,432E+003;158,9;;;;0,1868;;;;;;;1,586E-004;1,760E-003;21,00;9,1500
Oscillation Single Frequency (5);4,432E+003;159,0;;;;0,1867;;;;;;;1,589E-004;1,768E-003;21,00;9,1500
Oscillation Single Frequency (5);4,432E+003;159,1;;;;0,1867;;;;;;;1,591E-004;1,775E-003;21,00;9,1500
Oscillation Single Frequency (5);4,432E+003;159,1;;;;0,1866;;;;;;;1,593E-004;1,783E-003;21,00;9,1500
Oscillation Single Frequency (5);4,432E+003;159,2;;;;0,1865;;;;;;;1,594E-004;1,792E-003;21,00;9,1500
Oscillation Single Frequency (5);4,432E+003;159,3;;;;0,1866;;;;;;;1,596E-004;1,799E-003;21,00;9,1500
Oscillation Single Frequency (5);4,432E+003;159,4;;;;0,1867;;;;;;;1,596E-004;1,805E-003;21,00;9,1500
Oscillation Single Frequency (5);4,432E+003;159,5;;;;0,1871;;;;;;;1,596E-004;1,809E-003;21,00;9,1500
Oscillation Single Frequency (5);4,432E+003;159,5;;;;0,1870;;;;;;;1,596E-004;1,812E-003;21,00;9,1500
Oscillation Single Frequency (5);4,432E+003;159,6;;;;0,1866;;;;;;;1,596E-004;1,815E-003;21,00;9,1500
Oscillation Single Frequency (5);4,432E+003;159,7;;;;0,1868;;;;;;;1,595E-004;1,820E-003;21,00;9,1500
Oscillation Single Frequency (5);4,432E+003;159,8;;;;0,1866;;;;;;;1,593E-004;1,822E-003;21,00;9,1500
Oscillation Single Frequency (5);4,433E+003;159,8;;;;0,1868;;;;;;;1,592E-004;1,821E-003;21,00;9,1500
Oscillation Single Frequency (5);4,433E+003;159,9;;;;0,1865;;;;;;;1,589E-004;1,821E-003;21,00;9,1500
Oscillation Single Frequency (5);4,433E+003;160,0;;;;0,1862;;;;;;;1,587E-004;1,821E-003;21,00;9,1500
Oscillation Single Frequency (5);4,277E+003;3,984;;;;0,1854;24,2887;0,03292;3,798;14,02;6,917;15,64;1,597E-004;0,02308;21,00;9,1500
Oscillation Single Frequency (5);4,281E+003;7,969;;;;0,1852;4,56014;0,03292;3,797;70,87;43,73;83,27;1,597E-004;4,333E-003;21,00;9,1500
Oscillation Single Frequency (5);4,285E+003;12,03;;;;0,1858;3,32139;0,03292;3,797;108,1;37,37;114,3;1,597E-004;3,156E-003;21,00;9,1500
Oscillation Single Frequency (5);4,289E+003;16,02;;;;0,1856;3,21408;0,03292;3,797;117,7;9,927;118,1;1,597E-004;3,054E-003;21,00;9,1500
Oscillation Single Frequency (5);4,293E+003;20,00;;;;0,1851;2,95690;0,03292;3,797;126,6;21,31;128,4;1,597E-004;2,810E-003;21,00;9,1500
Oscillation Single Frequency (5);4,297E+003;23,98;;;;0,1852;3,28679;0,03292;3,797;113,0;23,84;115,5;1,597E-004;3,123E-003;21,00;9,1500
Oscillation Single Frequency (5);4,301E+003;27,97;;;;0,1850;3,35616;0,03292;3,797;112,2;14,52;113,1;1,597E-004;3,189E-003;21,00;9,1500
Oscillation Single Frequency (5);4,305E+003;32,03;;;;0,1854;3,18429;0,03292;3,797;118,1;16,24;119,2;1,597E-004;3,026E-003;21,00;9,1500
Oscillation Single Frequency (5);4,309E+003;36,02;;;;0,1851;3,19590;0,03292;3,797;117,4;17,99;118,8;1,597E-004;3,037E-003;21,00;9,1500
Oscillation Single Frequency (5);4,313E+003;40,00;;;;0,1850;3,41931;0,03292;3,797;109,5;18,31;111,1;1,597E-004;3,249E-003;21,00;9,1500
Oscillation Single Frequency (5);4,317E+003;43,98;;;;0,1851;3,25552;0,03292;3,797;116,6;1,668;116,6;1,597E-004;3,093E-003;21,00;9,1500
Oscillation Single Frequency (5);4,321E+003;47,97;;;;0,1856;2,93765;0,03292;3,797;127,1;23,25;129,3;1,597E-004;2,791E-003;21,00;9,1500
Oscillation Single Frequency (5);4,325E+003;52,03;;;;0,1854;3,25773;0,03292;3,797;115,0;19,14;116,6;1,597E-004;3,096E-003;21,00;9,1500
Oscillation Single Frequency (5);4,329E+003;56,01;;;;0,1853;3,45172;0,03292;3,797;107,9;21,46;110,0;1,597E-004;3,280E-003;21,00;9,1500
Oscillation Single Frequency (5);4,333E+003;60,00;;;;0,1854;3,27203;0,03292;3,797;115,9;5,402;116,1;1,597E-004;3,109E-003;21,00;9,1500
Oscillation Single Frequency (5);4,337E+003;63,98;;;;0,1852;2,96410;0,03292;3,797;126,1;22,62;128,1;1,597E-004;2,817E-003;21,00;9,1500
Oscillation Single Frequency (5);4,341E+003;67,97;;;;0,1856;3,39855;0,03292;3,797;110,3;17,53;111,7;1,597E-004;3,229E-003;21,00;9,1500
Oscillation Single Frequency (5);4,345E+003;72,03;;;;0,1851;3,26532;0,03292;3,797;115,8;11,12;116,3;1,597E-004;3,103E-003;21,00;9,1500
Oscillation Single Frequency (5);4,349E+003;76,01;;;;0,1857;3,17433;0,03292;3,797;119,4;7,506;119,6;1,597E-004;3,016E-003;21,00;9,1500
Oscillation Single Frequency (5);4,353E+003;80,00;;;;0,1857;2,92561;0,03292;3,797;127,8;22,73;129,8;1,597E-004;2,780E-003;21,00;9,1500
Oscillation Single Frequency (5);4,357E+003;83,98;;;;0,1861;3,44077;0,03292;3,797;108,7;19,09;110,4;1,597E-004;3,270E-003;21,00;9,1500
Oscillation Single Frequency (5);4,361E+003;87,97;;;;0,1861;3,23196;0,03292;3,797;117,4;5,022;117,5;1,597E-004;3,071E-003;21,00;9,1500
Oscillation Single Frequency (5);4,365E+003;92,03;;;;0,1856;3,11022;0,03292;3,797;121,1;15,11;122,1;1,597E-004;2,955E-003;21,00;9,1500
Oscillation Single Frequency (5);4,369E+003;96,01;;;;0,1866;3,19513;0,03292;3,797;117,5;17,75;118,8;1,597E-004;3,036E-003;21,00;9,1500
Oscillation Single Frequency (5);4,373E+003;100,0;;;;0,1861;3,47373;0,03292;3,797;107,8;17,96;109,3;1,597E-004;3,301E-003;21,00;9,1500
Oscillation Single Frequency (5);4,377E+003;104,0;;;;0,1857;3,21845;0,03292;3,797;118,0;0,7152;118,0;1,597E-004;3,058E-003;21,00;9,1500
Oscillation Single Frequency (5);4,381E+003;108,0;;;;0,1860;2,91891;0,03292;3,797;127,9;23,72;130,1;1,597E-004;2,774E-003;21,00;9,1500
Oscillation Single Frequency (5);4,385E+003;112,0;;;;0,1859;3,21569;0,03292;3,797;116,6;18,39;118,1;1,597E-004;3,056E-003;21,00;9,1500
Oscillation Single Frequency (5);4,389E+003;116,0;;;;0,1855;3,41789;0,03292;3,797;109,6;18,20;111,1;1,597E-004;3,248E-003;21,00;9,1500
Oscillation Single Frequency (5);4,393E+003;120,0;;;;0,1861;3,21711;0,03292;3,797;118,0;1,819;118,0;1,597E-004;3,057E-003;21,00;9,1500
Oscillation Single Frequency (5);4,397E+003;124,0;;;;0,1858;2,86783;0,03292;3,797;129,8;26,35;132,4;1,597E-004;2,725E-003;21,00;9,1500
Oscillation Single Frequency (5);4,401E+003;128,0;;;;0,1866;3,32705;0,03292;3,797;112,9;16,77;114,1;1,597E-004;3,161E-003;21,00;9,1500
Oscillation Single Frequency (5);4,405E+003;132,0;;;;0,1853;3,30543;0,03292;3,797;114,1;13,23;114,9;1,597E-004;3,141E-003;21,00;9,1500
Oscillation Single Frequency (5);4,409E+003;136,0;;;;0,1854;3,20181;0,03292;3,797;118,6;1,482;118,6;1,597E-004;3,042E-003;21,00;9,1500
Oscillation Single Frequency (5);4,413E+003;140,0;;;;0,1853;2,87618;0,03292;3,797;129,9;23,79;132,0;1,597E-004;2,733E-003;21,00;9,1500
Oscillation Single Frequency (5);4,417E+003;144,0;;;;0,1854;3,46451;0,03292;3,797;108,1;18,08;109,6;1,597E-004;3,292E-003;21,00;9,1500
Oscillation Single Frequency (5);4,421E+003;148,0;;;;0,1858;3,25411;0,03292;3,797;116,2;10,22;116,7;1,597E-004;3,092E-003;21,00;9,1500
Oscillation Single Frequency (5);4,425E+003;152,0;;;;0,1856;3,14814;0,03292;3,797;120,2;9,518;120,6;1,597E-004;2,991E-003;21,00;9,1500
Oscillation Single Frequency (5);4,429E+003;156,0;;;;0,1864;3,06293;0,03292;3,797;122,5;19,30;124,0;1,597E-004;2,910E-003;21,00;9,1500
Oscillation Single Frequency (5);4,433E+003;160,0;;;;0,1862;3,49305;0,03292;3,797;107,3;17,67;108,7;1,597E-004;3,319E-003;21,00;9,1500